Workbook

Sheet Raw Data
A2: Particulars | B2: FY2024 ($ m) | C2: FY2025 ($ m) | D2: FY2026 ($ m)
A3: Revenue | B3: 60922 | C3: 130497 | D3: 215938
A4: Cost of Revenue | B4: 16621 | C4: 32639 | D4: 62475
A5: Gross Profit | B5: 44301 | C5: 97858 | D5: 153463
A6: Operating Expenses | B6: 11329 | C6: 16405 | D6: 23076
A7: Operating Income | B7: 32972 | C7: 81453 | D7: 130387
A8: Income Before Tax | B8: 33818 | C8: 84026 | D8: 141450
A9: Income Tax Expense | B9: 4058 | C9: 11146 | D9: 21383
A10: Net Income | B10: 29760 | C10: 72880 | D10: 120067
A12: Additional details
A13: Particulars | B13: FY2024 | C13: FY2025 | D13: FY2026
A14: R&D Expense | B14: 8675 | C14: 12914 | D14: 18497
A15: SG&A Expense | B15: 2654 | C15: 3491 | D15: 4579
A16: Interest Income | B16: 866 | C16: 1786 | D16: 2300
A17: Interest Expense | B17: 257 | C17: 247 | D17: 259

Sheet Income Statement

Sheet Balance Sheet
A2: Consolidated Statements of Financial Position
A3: Particulars | B3: FY2024 ($ m) | C3: FY2025 ($ m) | D3: FY2026 ($ m)
A4: Cash & Cash Equivalents | B4: 7280 | C4: 8589 | D4: 10605
A5: Marketable Securities | B5: 18704 | C5: 34621 | D5: 51951
A6: Accounts Receivable | B6: 9999 | C6: 23065 | D6: 38466
A7: Inventories | B7: 5282 | C7: 10080 | D7: 21403
A8: Prepaid & Other Current Assets | B8: 3080 | C8: 3771 | D8: 3180
A9: Total Current Assets | B9: 44345 | C9: 80126 | D9: 125605
A10: Property & Equipment, Net | B10: 3914 | C10: 6283 | D10: 10383
A11: Operating Lease Assets | B11: 1346 | C11: 1793 | D11: 2867
A12: Goodwill | B12: 4430 | C12: 5188 | D12: 20832
A13: Intangible Assets, Net | B13: 1112 | C13: 807 | D13: 3306
A14: Deferred Income Tax Assets | B14: 6081 | C14: 10979 | D14: 13258
A15: Non-marketable Equity Securities | B15: 1321 | C15: 3387 | D15: 22251
... A31: Total liabilities and shareholders' equity | B31: 65728 | C31: 111601 | D31: 206803
A34: Average shareholder's equity | B34: =(22101+B30)/2 -> 32539.5 | C34: =(C30+B30)/2 -> 61152.5 | D34: =(D30+C30)/2 -> 118310
A35: Average Inventory | B35: =(5159+B7)/2 -> 5220.5 | C35: =(C7+B7)/2 -> 7681 | D35: =(D7+C7)/2 -> 15741.5
A36: Average Accoubts recievables | B36: =(B6+3827)/2 -> 6913 | C36: =(C6+B6)/2 -> 16532 | D36: =(D6+C6)/2 -> 30765.5
A37: Average Total Assets | B37: =(B17+41182)/2 -> 53455 | C37: =(C17+B17)/2 -> 88664.5 | D37: =(D17+C17)/2 -> 159202
A38: Total Debt | B38: =B20+B22 -> 9709 | C38: =C20+C22 -> 8463 | D38: =D20+D22 -> 8468

Sheet Cash Flow
A2: Consolidated Statements of Cash Flows
A3: Particulars | B3: FY2024 ($ m) | C3: FY2025 ($ m) | D3: FY2026 ($ m)
A4: Net Income | B4: 29760 | C4: 72880 | D4: 120067
A5: Stock-Based Compensation Expense | B5: 3549 | C5: 4737 | D5: 6386
A6: Depreciation & Amortization | B6: 1508 | C6: 1864 | D6: 2843
A7: Gains on Equity Securities, Net | B7: -238 | C7: -1030 | D7: -8918
A8: Deferred Income Taxes | B8: -2489 | C8: -4477 | D8: -1424
A9: Other | B9: -278 | C9: -502 | D9: -287
A10: Change in Accounts Receivable | B10: -6172 | C10: -13063 | D10: -15399
A11: Change in Inventories | B11: -98 | C11: -4781 | D11: -11324
A12: Change in Prepaid Expenses & Other Assets | B12: -1522 | C12: -395 | D12: 577
A13: Change in Accounts Payable | B13: 1531 | C13: 3357 | D13: 3096
A14: Change in Accrued & Other Current Liabilities | B14: 2025 | C14: 4278 | D14: 5257
A15: Change in Other Long-Term Liabilities | B15: 514 | C15: 1221 | D15: 1844
... A34: Net Cash Used in Financing Activities | B34: -13633 | C34: -42359 | D34: -48474
A36: Cash Reconciliation
A37: Particulars | B37: FY2024 ($ m) | C37: FY2025($ m) | D37: FY2026 ($ m)
A38: Net Cash from Operating Activities | B38: 28090 | C38: 64089 | D38: 102718
A39: Net Cash Used in Investing Activities | B39: -10566 | C39: -20421 | D39: -52228
A40: Net Cash Used in Financing Activities | B40: -13633 | C40: -42359 | D40: -48474
A41: Change in Cash & Cash Equivalents | B41: 3891 | C41: 1309 | D41: 2016
A42: Cash at Beginning of Period | B42: 3389 | C42: 7280 | D42: 8589
A43: Cash at End of Period | B43: 7280 | C43: 8589 | D43: 10605

Sheet Ratios
A3: Ratio | B3: FY2024 | C3: FY2025 | D3: FY2026
A4: Gross Margin | B4: =('Raw Data'!B5/'Raw Data'!B3)*100 -> 72.717573 | C4: =('Raw Data'!C5/'Raw Data'!C3)*100 -> 74.988697 | D4: =('Raw Data'!D5/'Raw Data'!D3)*100 -> 71.068084
A5: Net Margin | B5: =('Raw Data'!B10/'Raw Data'!B3)*100 -> 48.849348 | C5: =('Raw Data'!C10/'Raw Data'!C3)*100 -> 55.848027 | D5: =('Raw Data'!D10/'Raw Data'!D3)*100 -> 55.602534
A6: ROCE | B6: =('Raw Data'!B7/('Balance Sheet'!B17-'Balance Sheet'!B21))*100 -> 59.843549 | C6: =('Raw Data'!C7/('Balance Sheet'!C17-'Balance Sheet'!C21))*100 -> 87.065224 | D6: =('Raw Data'!D7/('Balance Sheet'!D17-'Balance Sheet'!D21))*100 -> 74.660444
A7: ROE | B7: =('Raw Data'!B10/'Balance Sheet'!B34)*100 -> 91.458074 | C7: =('Raw Data'!C10/'Balance Sheet'!C34)*100 -> 119.17747 | D7: =('Raw Data'!D10/'Balance Sheet'!D34)*100 -> 101.48508
A8: Current Ratio | B8: ='Balance Sheet'!B9/'Balance Sheet'!B21 -> 4.1712915 | C8: ='Balance Sheet'!C9/'Balance Sheet'!C21 -> 4.4398515 | D8: ='Balance Sheet'!D9/'Balance Sheet'!D21 -> 3.9052638
A9: Quick Ratio | B9: =('Balance Sheet'!B9-'Balance Sheet'!B7)/'Balance Sheet'!B21 -> 3.6744427 | C9: =('Balance Sheet'!C9-'Balance Sheet'!C7)/'Balance Sheet'!C21 -> 3.8813099 | D9: =('Balance Sheet'!D9-'Balance Sheet'!D7)/'Balance Sheet'!D21 -> 3.2398097
A10: Inventory Days | B10: =('Balance Sheet'!B35/'Raw Data'!B4)*365 -> 114.64307 | C10: =('Balance Sheet'!C35/'Raw Data'!C4)*365 -> 85.896167 | D10: =('Balance Sheet'!D35/'Raw Data'!D4)*365 -> 91.967147
A11: Receivable Days | B11: =('Balance Sheet'!B36/'Raw Data'!B3)*365 -> 41.417632 | C11: =('Balance Sheet'!C36/'Raw Data'!C3)*365 -> 46.23999 | D11: =('Balance Sheet'!D36/'Raw Data'!D3)*365 -> 52.002924
A12: Asset Turnover | B12: ='Raw Data'!B3/'Balance Sheet'!B37 -> 1.1396876 | C12: ='Raw Data'!C3/'Balance Sheet'!C37 -> 1.4718066 | D12: ='Raw Data'!D3/'Balance Sheet'!D37 -> 1.3563774
A13: Gearing | B13: =('Balance Sheet'!B38/'Balance Sheet'!B30)*100 -> 22.590628 | C13: =('Balance Sheet'!C38/'Balance Sheet'!C30)*100 -> 10.668499 | D13: =('Balance Sheet'!D38/'Balance Sheet'!D30)*100 -> 5.3835835
A14: Interest Cover | B14: ='Raw Data'!B7/'Raw Data'!B17 -> 128.29572 | C14: ='Raw Data'!C7/'Raw Data'!C17 -> 329.76923 | D14: ='Raw Data'!D7/'Raw Data'!D17 -> 503.42471

Sheet Dashboard Data
A3: 1. Revenue vs Net Income Trend
A4: Year | B4: Revenue ($m) | C4: Net Income ($m)
A5: FY2024 | B5: 60922 | C5: 29760
A6: FY2025 | B6: 130497 | C6: 72880
A7: FY2026 | B7: 215938 | C7: 120067
A16: 2. Profitability Ratio Trend
A17: Year | B17: Gross Margin | C17: Net Margin | D17: ROCE | E17: ROE
A18: FY2024 | B18: =Ratios!B4 -> 72.717573 | C18: =Ratios!B5 -> 48.849348 | D18: =Ratios!B6 -> 59.843549 | E18: =Ratios!B7 -> 91.458074
A19: FY2025 | B19: =Ratios!C4 -> 74.988697 | C19: =Ratios!C5 -> 55.848027 | D19: =Ratios!C6 -> 87.065224 | E19: =Ratios!C7 -> 119.17747
A20: FY2026 | B20: =Ratios!D4 -> 71.068084 | C20: =Ratios!D5 -> 55.602534 | D20: =Ratios!D6 -> 74.660444 | E20: =Ratios!D7 -> 101.48508
A29: 3. Liquidity Trend
A30: Year | B30: Current Ratio | C30: Quick Ratio
A31: FY2024 | B31: 4.17 | C31: 3.67
A32: FY2025 | B32: 4.44 | C32: 3.88
A33: FY2026 | B33: 3.9 | C33: 3.24
A41: 4. Efficiency Trend
A42: 4A. Working Capital Efficiency
A43: Year | B43: Inventory Days | C43: Receivable Days
A44: FY2024 | B44: =Ratios!B10 -> 114.64307 | C44: =Ratios!B11 -> 41.417632
A45: FY2025 | B45: 85.93 | C45: 46.25
A46: FY2026 | B46: 91.96 | C46: 52.01
A47: 4B. Asset Turnover
A48: Year | B48: Asset Turnover
A49: FY2024 | B49: =Ratios!B12 -> 1.1396876
A50: FY2025 | B50: 1.47
A51: FY2026 | B51: 1.36
A56: 5. Leverage Trend
A57: 5A. Gearing Trend
A58: Year | B58: Gearing
A59: FY2024 | B59: 0.2259
A60: FY2025 | B60: 0.1067
A61: FY2026 | B61: 0.0538
A62: 5B. Interest Cover Trend
A63: Year | B63: Interest Cover
A64: FY2024 | B64: 128.3
A65: FY2025 | B65: 329.77
A66: FY2026 | B66: 503.43
A71: 6. Cash Flow Trend
A72: Year | B72: Operating CF ($m) | C72: Investing CF ($m) | D72: Financing CF ($m)
A73: FY2024 | B73: 28090 | C73: -10566 | D73: -13633
...
